Workbook

Sheet support_tickets_data
A1: ticket_id | B1: customer_id | C1: issue_type | D1: issue_description | E1: priority | F1: date_submitted | G1: response_time_minutes | H1: resolution_time_minutes | I1: satisfaction_rating | J1: customer_comments | K1: agent_id | L1: resolved
A2: T0001 | B2: C0511 | C2: API Issue | D2: I'm pleased with how my issue was handled. Thanks! | E2: High | F2: 45010 | G2: 240 | H2: 927 | I2: 4 | J2: I'm pleased with how my issue was handled. Thanks! | K2: A004 | L2: TRUE
A3: T0002 | B3: C0729 | C3: Login Issue | D3: Excellent service! The agent went above and beyond. | E3: Low | F3: 45022 | G3: 223 | H3: 534 | I3: 5 | J3: The problem still persists. Not resolved yet. | K3: A004 | L3: FALSE
A4: T0003 | B4: C0439 | C4: Report Generation | D4: Resolution was satisfactory but could be improved. | E4: Low | F4: 45041 | G4: 214 | H4: 592 | I4: 1 | J4: The issue was escalated quickly, which was appreciated. | K4: A004 | L4: FALSE
A5: T0004 | B5: C0100 | C5: Data Import | D5: Agent was very helpful and polite. Great service! | E5: High | F5: 44977 | G5: 110 | H5: 864 | I5: 2 | J5: The issue was resolved quickly. Very satisfied! | K5: A003 | L5: TRUE
A6: T0005 | B6: C0258 | C6: Feature Request | D6: My issue was handled well, but follow-up could be better. | E6: Medium | F6: 44944 | G6: 151 | H6: 193 | I6: 2 | J6: The problem still persists. Not resolved yet. | K6: A004 | L6: FALSE
A7: T0006 | B7: C0526 | C7: Data Import | D7: It took too long to resolve the issue. Not happy. | E7: Low | F7: 45087 | G7: 134 | H7: 194 | I7: 2 | J7: This is the second time I'm facing this issue. Frustrating! | K7: A002 | L7: TRUE
A8: T0007 | B8: C0415 | C8: Feature Request | D8: It took too long to resolve the issue. Not happy. | E8: High | F8: 44936 | G8: 64 | H8: 232 | I8: 1 | J8: The support team was unresponsive at first. | K8: A001 | L8: FALSE
A9: T0008 | B9: C0602 | C9: Login Issue | D9: Resolution was satisfactory but could be improved. | E9: Critical | F9: 44979 | G9: 132 | H9: 578 | I9: 5 | J9: Good support but the resolution could have been faster. | K9: A002 | L9: TRUE
A10: T0009 | B10: C0934 | C10: API Issue | D10: It took too long to resolve the issue. Not happy. | E10: High | F10: 45100 | G10: 57 | H10: 46 | I10: 4 | J10: This is the second time I'm facing this issue. Frustrating! | K10: A004 | L10: FALSE
A11: T0010 | B11: C0410 | C11: Feature Request | D11: Good support but the resolution could have been faster. | E11: Critical | F11: 45013 | G11: 223 | H11: 1230 | I11: 3 | J11: This was a critical issue that took too long to resolve. | K11: A002 | L11: TRUE
A12: T0011 | B12: C0966 | C12: Report Generation | D12: Agent was very helpful and polite. Great service! | E12: High | F12: 44997 | G12: 192 | H12: 1284 | I12: 2 | J12: The issue was ignored for too long. Disappointing. | K12: A001 | L12: FALSE
A13: T0012 | B13: C0342 | C13: Billing Issue | D13: Excellent service! The agent went above and beyond. | E13: Low | F13: 45053 | G13: 35 | H13: 757 | I13: 4 | J13: The issue was ignored for too long. Disappointing. | K13: A003 | L13: TRUE
... A51: T0050 | B51: C0941 | C51: Billing Issue | D51: The agent understood my problem and solved it efficiently. | E51: Medium | F51: 44927 | G51: 106 | H51: 1330 | I51: 4 | J51: Happy with the response time but the resolution was lacking. | K51: A005 | L51: FALSE

Sheet analysis
A1: SUPPORT TICKETS ANALYSIS REPORT
A3: 1. OVERALL STATISTICS
A4: Total Tickets | B4: 50
A5: Resolved Tickets | B5: 23 | C5: 46%
A6: Unresolved Tickets | B6: 27 | C6: 54%
A8: 2. ISSUE TYPE DISTRIBUTION
A9: Issue Type | B9: Count | C9: Percentage
A10: Data Import | B10: 11 | C10: 22%
A11: Billing Issue | B11: 10 | C11: 20%
A12: API Issue | B12: 6 | C12: 12%
A13: UI Bug | B13: 6 | C13: 12%
A14: Feature Request | B14: 6 | C14: 12%
A15: Login Issue | B15: 6 | C15: 12%
A16: Report Generation | B16: 5 | C16: 10%
A18: 3. PRIORITY ANALYSIS
A19: Priority Level | B19: Count | C19: Resolution Rate
A20: Critical | B20: 6 | C20: 50%
A21: High | B21: 15 | C21: 40%
A22: Medium | B22: 11 | C22: 36%
A23: Low | B23: 18 | C23: 56%
A25: 4. RESPONSE TIME ANALYSIS
A26: Average Response Time | B26: 129 min | C26: 2.15 hours
A27: Min Response Time | B27: 15 min
A28: Max Response Time | B28: 240 min | C28: 4 hours
A30: 5. RESOLUTION TIME ANALYSIS
A31: Average Resolution Time | B31: 675 min | C31: 11.25 hours
A32: Min Resolution Time | B32: 46 min
A33: Max Resolution Time | B33: 1363 min | C33: 22.7 hours
A35: 6. CUSTOMER SATISFACTION
A36: Average Rating | B36: 2.84 | C36: out of 5
A37: Rating 5 (Excellent) | B37: 7 | C37: 14%
A38: Rating 4 (Good) | B38: 13 | C38: 26%
A39: Rating 3 (Average) | B39: 8 | C39: 16%
A40: Rating 2 (Below Average) | B40: 12 | C40: 24%
A41: Rating 1 (Poor) | B41: 10 | C41: 20%
A43: 7. AGENT PERFORMANCE
A44: Agent | B44: Tickets Handled | C44: Resolution Rate
A45: A004 | B45: 16 | C45: 44%
A46: A003 | B46: 10 | C46: 50%
A47: A002 | B47: 8 | C47: 50%
...

Sheet Analysis_Report
A1: SUPPORT TICKETS ANALYSIS REPORT
A3: 1. EXECUTIVE SUMMARY
A5: Metric | B5: Value
A6: Total Tickets | B6: ==COUNTA(support_tickets_data!A2:A51)
A7: Resolved Tickets | B7: ==COUNTIF(support_tickets_data!L2:L51,TRUE)
A8: Unresolved Tickets | B8: ==COUNTIF(support_tickets_data!L2:L51,FALSE)
A9: Resolution Rate | B9: ==B7/B6
A10: Avg Response Time (min) | B10: ==AVERAGE(support_tickets_data!G2:G51)
A11: Avg Resolution Time (min) | B11: ==AVERAGE(support_tickets_data!H2:H51)
A12: Avg Satisfaction Rating | B12: ==AVERAGE(support_tickets_data!I2:I51)
A14: 2. ISSUE TYPE BREAKDOWN
A16: Issue Type | B16: Count | C16: Percentage
A17: API Issue | B17: ==COUNTIF(support_tickets_data!C2:C51,"API Issue") | C17: ==B17/$B$6
A18: Billing Issue | B18: ==COUNTIF(support_tickets_data!C2:C51,"Billing Issue") | C18: ==B18/$B$6
A19: Data Import | B19: ==COUNTIF(support_tickets_data!C2:C51,"Data Import") | C19: ==B19/$B$6
A20: Feature Request | B20: ==COUNTIF(support_tickets_data!C2:C51,"Feature Request") | C20: ==B20/$B$6
A21: Login Issue | B21: ==COUNTIF(support_tickets_data!C2:C51,"Login Issue") | C21: ==B21/$B$6
A22: Report Generation | B22: ==COUNTIF(support_tickets_data!C2:C51,"Report Generation") | C22: ==B22/$B$6
A23: UI Bug | B23: ==COUNTIF(support_tickets_data!C2:C51,"UI Bug") | C23: ==B23/$B$6
A24: TOTAL | B24: ==SUM(B17:B23) | C24: ==SUM(C17:C23)
A26: 3. PRIORITY LEVEL ANALYSIS
A28: Priority | B28: Count | C28: Avg Resolution Time | D28: Resolution Rate
A29: Critical | B29: ==COUNTIF(support_tickets_data!E2:E51,"Critical") | C29: ==AVERAGEIF(support_tickets_data!E2:E51,"Critical",support_tickets_data!H2:H51) | D29: ==COUNTIFS(support_tickets_data!E2:E51,"Critical",support_tickets_data!L2:L51,TRUE)/B29
A30: High | B30: ==COUNTIF(support_tickets_data!E2:E51,"High") | C30: ==AVERAGEIF(support_tickets_data!E2:E51,"High",support_tickets_data!H2:H51) | D30: ==COUNTIFS(support_tickets_data!E2:E51,"High",support_tickets_data!L2:L51,TRUE)/B30
A31: Medium | B31: ==COUNTIF(support_tickets_data!E2:E51,"Medium") | C31: ==AVERAGEIF(support_tickets_data!E2:E51,"Medium",support_tickets_data!H2:H51) | D31: ==COUNTIFS(support_tickets_data!E2:E51,"Medium",support_tickets_data!L2:L51,TRUE)/B31
A32: Low | B32: ==COUNTIF(support_tickets_data!E2:E51,"Low") | C32: ==AVERAGEIF(support_tickets_data!E2:E51,"Low",support_tickets_data!H2:H51) | D32: ==COUNTIFS(support_tickets_data!E2:E51,"Low",support_tickets_data!L2:L51,TRUE)/B32
A33: TOTAL | B33: ==SUM(B29:B32) | C33: ==AVERAGE(C29:C32) | D33: ==AVERAGE(D29:D32)
A35: 4. CUSTOMER SATISFACTION ANALYSIS
A37: Rating | B37: Count | C37: Percentage
A38: 1 Star | B38: ==COUNTIF(support_tickets_data!I2:I51,1) | C38: ==B38/$B$6
A39: 2 Stars | B39: ==COUNTIF(support_tickets_data!I2:I51,2) | C39: ==B39/$B$6
A40: 3 Stars | B40: ==COUNTIF(support_tickets_data!I2:I51,3) | C40: ==B40/$B$6
A41: 4 Stars | B41: ==COUNTIF(support_tickets_data!I2:I51,4) | C41: ==B41/$B$6
A42: 5 Stars | B42: ==COUNTIF(support_tickets_data!I2:I51,5) | C42: ==B42/$B$6
A43: TOTAL | B43: ==SUM(B38:B42) | C43: ==SUM(C38:C42)
A45: 5. AGENT PERFORMANCE ANALYSIS
A47: Agent | B47: Tickets Handled | C47: Resolved | D47: Avg Satisfaction | E47: Avg Resolution Time
A48: A001 | B48: ==COUNTIF(support_tickets_data!K2:K51,"A001") | C48: ==COUNTIFS(support_tickets_data!K2:K51,"A001",support_tickets_data!L2:L51,TRUE) | D48: ==AVERAGEIF(support_tickets_data!K2:K51,"A001",support_tickets_data!I2:I51) | E48: ==AVERAGEIF(support_tickets_data!K2:K51,"A001",support_tickets_data!H2:H51)
A49: A002 | B49: ==COUNTIF(support_tickets_data!K2:K51,"A002") | C49: ==COUNTIFS(support_tickets_data!K2:K51,"A002",support_tickets_data!L2:L51,TRUE) | D49: ==AVERAGEIF(support_tickets_data!K2:K51,"A002",support_tickets_data!I2:I51) | E49: ==AVERAGEIF(support_tickets_data!K2:K51,"A002",support_tickets_data!H2:H51)
A50: A003 | B50: ==COUNTIF(support_tickets_data!K2:K51,"A003") | C50: ==COUNTIFS(support_tickets_data!K2:K51,"A003",support_tickets_data!L2:L51,TRUE) | D50: ==AVERAGEIF(support_tickets_data!K2:K51,"A003",support_tickets_data!I2:I51) | E50: ==AVERAGEIF(support_tickets_data!K2:K51,"A003",support_tickets_data!H2:H51)
...
